Workbook
Name Slicer_Currently_residing_in_which_Regional_Council?: #N/A

Sheet National Pivot
A1: Last Year Enrollment | B1: (All)
H2: Specialization | I2: (blank)
A3: Row Labels | B3: Total Enrollment | C3: Sum of Count for Candiodates started course | D3: Sum of One verses Program Registered
A4: Southern | B4: 585 | C4: 501 | D4: 840 | H4: Row Labels | I4: Count of Unique Id
A5: Central | B5: 396 | C5: 301 | D5: 448 | H5: Central | I5: 95
A6: Gilgit | B6: 245 | C6: 173 | D6: 235 | H6: Southern | I6: 84
A7: Lower Chitral | B7: 112 | C7: 77 | D7: 127 | H7: Gilgit | I7: 72
A8: Hunza | B8: 111 | C8: 76 | D8: 107 | H8: Lower Chitral | I8: 35
A9: Ishkoman Puniyal | B9: 84 | C9: 64 | D9: 86 | H9: Hunza | I9: 35
A10: Upper Chitral | B10: 74 | C10: 55 | D10: 84 | H10: National | I10: 34
A11: Gupis Yasin | B11: 72 | C11: 60 | D11: 85 | H11: Ishkoman Puniyal | I11: 20
A12: National | B12: 53 | C12: 19 | D12: 26 | H12: Upper Chitral | I12: 19
A13: (blank) | H13: Gupis Yasin | I13: 12
A14: Grand Total | B14: 1732 | C14: 1326 | D14: 2038 | H14: (blank)
H15: Grand Total | I15: 406
G30: Completed | H30: No | K30: Completed | L30: No | O30: Completed | P30: No
A31: Completion % | B31: 1 | G31: Completion % | H31: (Multiple Items) | K31: Completion % | L31: 0 | O31: Completion % | P31: (Multiple Items)
A33: Row Labels | B33: Total Enrollment | C33: Count of Count for Yes | G33: Row Labels | H33: Total Enrollment | I33: Count of Specialization | K33: Row Labels | L33: Total Enrollment | M33: Count of Specialization | O33: Row Labels | P33: Total Enrollment | Q33: Count of Specialization
A34: Southern | B34: 134 | C34: 211 | G34: Southern | H34: 128 | I34: 232 | K34: Southern | L34: 200 | M34: 336 | O34: Southern | P34: 39 | Q34: 61
A35: Central | B35: 42 | C35: 47 | G35: Central | H35: 97 | I35: 144 | K35: Central | L35: 151 | M35: 242 | O35: Central | P35: 11 | Q35: 15
A36: Gilgit | B36: 26 | C36: 30 | G36: Gilgit | H36: 54 | I36: 77 | K36: Gilgit | L36: 87 | M36: 118 | O36: Gilgit | P36: 6 | Q36: 10
A37: Lower Chitral | B37: 13 | C37: 16 | G37: Hunza | H37: 29 | I37: 40 | K37: Ishkoman Puniyal | L37: 43 | M37: 58 | O37: Lower Chitral | P37: 6 | Q37: 10
A38: Hunza | B38: 10 | C38: 11 | G38: Lower Chitral | H38: 28 | I38: 44 | K38: Hunza | L38: 32 | M38: 49 | O38: Hunza | P38: 5 | Q38: 7
A39: Gupis Yasin | B39: 9 | C39: 10 | G39: Gupis Yasin | H39: 23 | I39: 29 | K39: Lower Chitral | L39: 30 | M39: 57 | O39: Gupis Yasin | P39: 4 | Q39: 9
A40: Upper Chitral | B40: 8 | C40: 10 | G40: Upper Chitral | H40: 17 | I40: 28 | K40: Upper Chitral | L40: 28 | M40: 44 | O40: Ishkoman Puniyal | P40: 3 | Q40: 3
A41: Ishkoman Puniyal | B41: 4 | C41: 5 | G41: Ishkoman Puniyal | H41: 14 | I41: 20 | K41: Gupis Yasin | L41: 24 | M41: 37 | O41: National | P41: 2 | Q41: 2
A42: National | B42: 1 | C42: 1 | G42: National | H42: 6 | I42: 8 | K42: National | L42: 10 | M42: 15 | O42: Upper Chitral | P42: 2 | Q42: 2
A43: Grand Total | B43: 247 | C43: 341 | G43: Grand Total | H43: 396 | I43: 622 | K43: Grand Total | L43: 605 | M43: 956 | O43: Grand Total | P43: 78 | Q43: 119
A52: Row Labels | B52: Total Candidates | C52: Course Started | D52: Course not Started
A53: Student | B53: 599 | C53: 474 | D53: 125
A54: Employed | B54: 470 | C54: 391 | D54: 79
A55: Unemployed | B55: 337 | C55: 263 | D55: 74
A56: Fresh Graduate | B56: 118 | C56: 92 | D56: 26
A57: Data not available | B57: 114 | C57: 33 | D57: 81
A58: Self Employed | B58: 64 | C58: 52 | D58: 12
A59: Entrepreneur | B59: 30 | C59: 21 | D59: 9
A60: (blank) | D60: 0
A61: Grand Total | B61: 1732 | C61: 1326 | D61: 406
A65: Row Labels | B65: Course Started | C65: Course Not started
A66: Below 25,000 | B66: 102 | C66: 33
...

Sheet Regions Pivot
A1: Currently residing in which Regional Council? | B1: Southern (Karachi / Interior Sindh) | I1: Currently residing in which Regional Council? | J1: Southern (Karachi / Interior Sindh) | P1: =B1 -> Southern (Karachi / Interior Sindh)
I2: Specialization | J2: (blank)
A3: Row Labels | B3: Sum of Count for Enrollment | C3: Sum of Count for Candiodates started course | D3: Count of Specialization
A4: Karimabad_Southern Region | B4: 149 | C4: 135 | D4: 237 | I4: Row Labels | J4: Count of Unique Id
A5: Garden_Southern Region | B5: 141 | C5: 114 | D5: 187 | I5: Garden_Southern Region | J5: 27
A6: Gulshan_Southern Region | B6: 139 | C6: 128 | D6: 235 | I6: Gulshan_Southern Region | J6: 11
A7: Hyderabad_Southern Region | B7: 50 | C7: 39 | D7: 63 | I7: Hyderabad_Southern Region | J7: 11
A8: Kharadar_Southern Region | B8: 42 | C8: 35 | D8: 50 | I8: Karimabad_Southern Region | J8: 14
A9: Thatta & Shah Bunder_Southern Region | B9: 30 | C9: 27 | D9: 38 | I9: Kharadar_Southern Region | J9: 7
A10: Tando Turel_Southern Region | B10: 21 | C10: 18 | D10: 25 | I10: Not available in Google Form Data | J10: 8
A11: Not available in Google Form Data | B11: 13 | C11: 5 | D11: 5 | I11: Tando Turel_Southern Region | J11: 3
A12: Grand Total | B12: 585 | C12: 501 | D12: 840 | I12: Thatta & Shah Bunder_Southern Region | J12: 3
I13: Grand Total | J13: 84
A26: Currently residing in which Regional Council? | B26: Southern (Karachi / Interior Sindh) | E26: Currently residing in which Regional Council? | F26: Southern (Karachi / Interior Sindh) | J26: Currently residing in which Regional Council? | K26: Southern (Karachi / Interior Sindh) | P26: Currently residing in which Regional Council? | Q26: Southern (Karachi / Interior Sindh)
A27: Completion % | B27: 1 | E27: Completion % | F27: (Multiple Items) | J27: Completion % | K27: (Multiple Items) | P27: Completion % | Q27: (Multiple Items)
A29: Row Labels | B29: Candidates | C29: Courses Completed | E29: Row Labels | F29: Candidates | G29: Courses Completed | J29: Row Labels | K29: Candidates | L29: Courses Completed | P29: Row Labels | Q29: Candidates | R29: Courses Completed
A30: Gulshan_Southern Region | B30: 43 | C30: 75 | E30: Gulshan_Southern Region | F30: 13 | G30: 26 | J30: Karimabad_Southern Region | K30: 35 | L30: 74 | P30: Karimabad_Southern Region | Q30: 55 | R30: 93
A31: Karimabad_Southern Region | B31: 34 | C31: 54 | E31: Karimabad_Southern Region | F31: 11 | G31: 16 | J31: Gulshan_Southern Region | K31: 34 | L31: 62 | P31: Garden_Southern Region | Q31: 49 | R31: 89
A32: Garden_Southern Region | B32: 32 | C32: 45 | E32: Garden_Southern Region | F32: 7 | G32: 9 | J32: Garden_Southern Region | K32: 28 | L32: 46 | P32: Gulshan_Southern Region | Q32: 38 | R32: 72
A33: Thatta & Shah Bunder_Southern Region | B33: 10 | C33: 13 | E33: Thatta & Shah Bunder_Southern Region | F33: 2 | G33: 2 | J33: Hyderabad_Southern Region | K33: 11 | L33: 22 | P33: Hyderabad_Southern Region | Q33: 19 | R33: 26
A34: Hyderabad_Southern Region | B34: 7 | C34: 12 | E34: Tando Turel_Southern Region | F34: 2 | G34: 2 | J34: Kharadar_Southern Region | K34: 8 | L34: 11 | P34: Kharadar_Southern Region | Q34: 19 | R34: 28
A35: Kharadar_Southern Region | B35: 6 | C35: 8 | E35: Hyderabad_Southern Region | F35: 2 | G35: 3 | J35: Tando Turel_Southern Region | K35: 6 | L35: 7 | P35: Thatta & Shah Bunder_Southern Region | Q35: 10 | R35: 14
A36: Tando Turel_Southern Region | B36: 2 | C36: 4 | E36: Kharadar_Southern Region | F36: 2 | G36: 3 | J36: Thatta & Shah Bunder_Southern Region | K36: 5 | L36: 9 | P36: Tando Turel_Southern Region | Q36: 8 | R36: 12
A37: Grand Total | B37: 134 | C37: 211 | E37: Grand Total | F37: 39 | G37: 61 | J37: Not available in Google Form Data | K37: 2 | L37: 2 | P37: Not available in Google Form Data | Q37: 3 | R37: 3
J38: Grand Total | K38: 129 | L38: 233 | P38: Grand Total | Q38: 201 | R38: 337
A45: Currently residing in which Regional Council? | B45: Southern (Karachi / Interior Sindh)
A47: Count of Name | B47: Column Labels
A48: Row Labels | B48: On Zero % | C48: <20% | D48: <30% | E48: <40% | F48: <50% | G48: <75% | H48: <85% | I48: <99% | J48: On 100% | K48: Grand Total
A49: Google Data Analytics | B49: 80 | C49: 32 | D49: 10 | E49: 12 | F49: 12 | G49: 16 | I49: 1 | J49: 15 | K49: 178
A50: Google AI Essentials | B50: 34 | C50: 11 | E50: 2 | G50: 2 | H50: 3 | J50: 86 | K50: 138
A51: Google Digital Marketing & E-commerce | B51: 60 | C51: 15 | D51: 11 | E51: 10 | F51: 9 | G51: 8 | J51: 20 | K51: 133
A52: Google Project Management | B52: 34 | C52: 13 | D52: 9 | F52: 10 | G52: 11 | H52: 1 | J52: 12 | K52: 90
A53: Google Prompting Essentials | B53: 27 | D53: 8 | F53: 5 | G53: 2 | J53: 45 | K53: 87
A54: Google Cybersecurity | B54: 27 | C54: 8 | D54: 1 | E54: 5 | F54: 3 | G54: 9 | H54: 1 | J54: 7 | K54: 61
A55: Google Advanced Data Analytics | B55: 25 | C55: 7 | D55: 4 | G55: 2 | J55: 7 | K55: 45
A56: Google IT Support | B56: 16 | C56: 8 | E56: 1 | G56: 1 | J56: 6 | K56: 32
A57: Google Business Intelligence | B57: 14 | D57: 5 | F57: 1 | J57: 5 | K57: 25
A58: Google IT Automation with Python | B58: 10 | C58: 6 | D58: 1 | F58: 1 | H58: 3 | J58: 3 | K58: 24
A59: Google UX Design | B59: 5 | C59: 8 | E59: 3 | F59: 1 | G59: 1 | J59: 5 | K59: 23
A60: Google Marketing Digital e E-Commerce | B60: 3 | K60: 3
...

Sheet Data
A1: Count for Enrollment | B1: Count for Yes | C1: One verses Program Registered | D1: Count for Candiodates started course | E1: Unique Id | F1: Serial no. | G1: Name | H1: Email | I1: External Id | J1: Specialization | K1: Specialization Slug | L1: University | M1: Enrollment Time | N1: Last Specialization Activity Time | O1: # Completed Courses | P1: # Courses in Specialization | Q1: Completed | R1: Removed From Program | S1: Program Slug | T1: Program Name | U1: Enrollment Source | V1: Specialization Completion Time | W1: Specialization Certificate URL | X1: Is Contract Active | Y1: Last Year Enrollment | Z1: Completion % | AA1: Completion Range | AB1: Your Phone Number Please enter your contact number in the following format: 0300xxxxxxx (11 digits)* | AC1: CNIC as per Master Data | AD1: Date of Birth | AE1: Currently residing in which Regional Council? | AF1: Local Council? | AG1: Jk currently attending? | AH1: Gender | AI1: Marital Status | AJ1: What is your current Profession? | AK1: Family Income Band | AL1: Future Interest regarding Placement | AM1: Age Bracket | AN1: Qualification
A2: 1 | B2: 0 | C2: 1 | D2: 1 | E2: tahirsahil807@gmail.comGoogle Project Management | F2: 1 | G2: Tahir Hussain | H2: tahirsahil807@gmail.com | I2: 7140199480925 | J2: Google Project Management | K2: google-project-management | L2: Google | M2: 2025-07-24T03:27:06.743Z | N2: 2025-07-24T04:01:20.611Z | O2: 0 | P2: 7 | Q2: No | R2: No | S2: akepb-gilgit-male-gxr0q | T2: AKEPB - Gilgit II (Male) | Y2: No | Z2: 0 | AA2: On Zero % | AB2: +923160895010 | AC2: 7140199480925 | AD2: 34982 | AE2: Gilgit | AF2: Gilgit_Gilgit Region | AG2: Noorabad jamatkhana | AH2: Male | AI2: Married | AJ2: Self Employed | AK2: 25,000 - 50,000 | AL2: Support My Family members for Upskilling | AM2: 26-35 | AN2: Masters
A3: 1 | B3: 0 | C3: 1 | D3: 1 | E3: nizarbahadur65@gmail.comGoogle Data Analytics | F3: 2 | G3: Nizar Bahadur | H3: nizarbahadur65@gmail.com | I3: 7140240244219 | J3: Google Data Analytics | K3: google-data-analytics | L3: Google | M3: 2025-08-22T07:08:44.148Z | N3: 2025-09-21T07:41:19.439Z | O3: 0 | P3: 9 | Q3: No | R3: No | S3: akepb-central-male-qoy2h | T3: AKEPB - Central (Male) | U3: Google Career Certificates Scholarship Program | Y3: No | Z3: 0 | AA3: On Zero % | AB3: +923169546084 | AC3: 7140240244219 | AD3: 38148 | AE3: Central (Rawalpindi / Lahore / Interior Punjab / Peshawar / etc) | AF3: Peshawar_Central Region | AG3: Amin colony JK | AH3: Male | AI3: Single | AJ3: Student | AK3: 80,001 - 100,000 | AL3: Advanced technical or soft skills training | AM3: 18-25 | AN3: Bachelors
A4: 1 | B4: 0 | C4: 1 | D4: 1 | E4: riazhaikal44@gmail.comGoogle Cybersecurity | F4: 3 | G4: Riazahmad | H4: riazhaikal44@gmail.com | I4: 7170203427469 | J4: Google Cybersecurity | K4: google-cybersecurity | L4: Google | M4: 2025-08-04T16:22:12.487Z | O4: 0 | P4: 9 | Q4: No | R4: No | S4: akepb-central-male-qoy2h | T4: AKEPB - Central (Male) | U4: Google Career Certificates Scholarship Program | V4: GgvHw | Y4: No | Z4: 0 | AA4: On Zero % | AB4: +923170566335 | AC4: 7170203427469 | AD4: 37398 | AE4: Central (Rawalpindi / Lahore / Interior Punjab / Peshawar / etc) | AF4: Rawalpindi_Central Region | AG4: Apara jk | AH4: Male | AI4: Single | AJ4: Student | AK4: 60,000 - 80,000 | AL4: Advanced technical or soft skills training | AM4: 18-25 | AN4: FSc
A5: 0 | B5: 1 | D5: 0 | E5: hasnain.ux@gmail.comGoogle Project Management | F5: 4 | G5: Hasnain Karim | H5: hasnain.ux@gmail.com | I5: 7170303412029 | J5: Google Project Management | K5: google-project-management | L5: Google | M5: 2025-09-03T14:30:29.941Z | N5: 2025-10-16T08:17:33.646Z | O5: 1 | P5: 7 | Q5: No | R5: No | S5: akepb-gilgit-male-gxr0q | T5: AKEPB - Gilgit II (Male) | U5: Google Career Certificates Scholarship Program | V5: xCh7v | Y5: No | Z5: 0.14285714 | AA5: <20% | AB5: +923465760321 | AC5: 7170303412029 | AD5: 37194 | AE5: Gilgit | AF5: Gilgit_Gilgit Region | AG5: Sonikot | AH5: Male | AI5: Single | AJ5: Employed | AK5: 25,000 - 50,000 | AL5: Support My Family members for Upskilling | AM5: 18-25 | AN5: FSc
A6: 1 | B6: 0 | C6: 1 | D6: 1 | E6: alirajpootuk0@gmail.comGoogle Data Analytics | F6: 5 | G6: Ali Hussnain | H6: alirajpootuk0@gmail.com | I6: 3430125604137 | J6: Google Data Analytics | K6: google-data-analytics | L6: Google | M6: 2025-07-23T19:24:26.198Z | N6: 2025-11-03T22:18:08.344Z | O6: 1 | P6: 9 | Q6: No | R6: No | S6: akepb-central-male-qoy2h | T6: AKEPB - Central (Male) | U6: Google Career Certificates Scholarship Program | Y6: No | Z6: 0.11111111 | AA6: <20% | AB6: +923472055937 | AC6: 3430125604137 | AD6: 33912 | AE6: Central (Rawalpindi / Lahore / Interior Punjab / Peshawar / etc) | AF6: Hafizabad_Central Region | AG6: Main jk | AH6: Male | AI6: Married | AJ6: Employed | AK6: 25,000 - 50,000 | AL6: Support My Family members for Upskilling | AM6: 26-35 | AN6: FSc
A7: 1 | B7: 0 | C7: 1 | D7: 1 | E7: knameera825@gmail.comGoogle Data Analytics | F7: 6 | G7: Nameera khan | H7: knameera825@gmail.com | I7: 4240159619200 | J7: Google Data Analytics | K7: google-data-analytics | L7: Google | M7: 2025-07-29T10:36:49.216Z | N7: 2025-10-31T07:45:39.624Z | O7: 5 | P7: 9 | Q7: No | R7: No | S7: akepb-gilgit-female-1kkb4 | T7: AKEPB - Gilgit II (Female) | U7: Google Career Certificates Scholarship Program | V7: xCh7v | Y7: No | Z7: 0.55555556 | AA7: <75% | AB7: +923434000818 | AC7: 4240159619200 | AD7: 36972 | AE7: Gilgit | AF7: Gilgit_Gilgit Region | AG7: jamatkhana # 03 Nomal | AH7: Female | AI7: Single | AJ7: Fresh Graduate | AK7: 60,000 - 80,000 | AL7: Advanced technical or soft skills training | AM7: 18-25 | AN7: Below Matric
A8: 0 | B8: 0 | D8: 0 | E8: siduuusidra2006@gmail.comGoogle Project Management | F8: 7 | G8: Sidar Tul Muntaha | H8: siduuusidra2006@gmail.com | I8: 7140305827396 | J8: Google Project Management | K8: google-project-management | L8: Google | M8: 2025-08-04T11:46:00.022Z | N8: 2025-08-04T12:20:40.715Z | O8: 0 | P8: 7 | Q8: No | R8: No | S8: akepb-central-female-g5ddm | T8: AKEPB - Central (Female) | V8: xCh7v | Y8: No | Z8: 0 | AA8: On Zero % | AB8: +923197829316 | AC8: 7140305827396 | AD8: 38786 | AE8: Central (Rawalpindi / Lahore / Interior Punjab / Peshawar / etc) | AF8: Rawalpindi_Central Region | AG8: Rawalpindi JK | AH8: Female | AI8: Single | AJ8: Student | AK8: 25,000 - 50,000 | AL8: Internship placements | AM8: 18-25 | AN8: FSc
A9: 1 | B9: 0 | C9: 1 | D9: 1 | E9: adilkamalkhan3@gmail.comGoogle AI Essentials | F9: 8 | G9: Aadil Kamal Khan | H9: adilkamalkhan3@gmail.com | I9: 1520261333007 | J9: Google AI Essentials | K9: ai-essentials-google | L9: Google | M9: 2025-11-01T04:30:49.475Z | N9: 2025-11-01T05:52:03.425Z | O9: 1 | P9: 5 | Q9: No | R9: No | S9: akepb-central-male-qoy2h | T9: AKEPB - Central (Male) | V9: GgvHw | Y9: No | Z9: 0.2 | AA9: <20% | AB9: Not available in Google Form Data | AC9: Not available in Google Form Data | AD9: Not available in Google Form Data | AE9: Central (Rawalpindi / Lahore / Interior Punjab / Peshawar / etc) | AF9: Not available in Google Form Data | AG9: Not available in Google Form Data | AH9: Not available in Google Form Data | AI9: Not available in Google Form Data | AJ9: Not available in Google Form Data | AK9: Not available in Google Form Data | AL9: Not available in Google Form Data | AM9: Not available in Google Form Data | AN9: Not available in Google Form Data
A10: 0 | B10: 0 | D10: 0 | E10: reenaalim4@gmail.comGoogle Business Intelligence | F10: 9 | G10: Reena | H10: reenaalim4@gmail.com | I10: 7140405807386 | J10: Google Business Intelligence | K10: google-business-intelligence | L10: Google | M10: 2025-10-09T16:51:11.541Z | N10: 2025-10-09T17:06:39.912Z | O10: 0 | P10: 3 | Q10: No | R10: No | S10: akepb-gilgit-female-1kkb4 | T10: AKEPB - Gilgit II (Female) | U10: Google Career Certificates Scholarship Program | V10: GgvHw | Y10: No | Z10: 0 | AA10: On Zero % | AB10: +923428684372 | AC10: 7140405807386 | AD10: 38717 | AE10: Gilgit | AF10: Chatoorkhand_Ishkoman & Puniyal Region | AG10: Center jamat khana Chatorkhand | AH10: Female | AI10: Single | AJ10: Student | AK10: 60,000 - 80,000 | AL10: Entrepreneurship support and mentoring | AM10: 18-25 | AN10: Bachelors
A11: 0 | B11: 0 | D11: 0 | E11: ahtishambulbul4@gmail.comGoogle Data Analytics | F11: 10 | G11: Ahtisham bulbul | H11: ahtishambulbul4@gmail.com | I11: 7140108770097 | J11: Google Data Analytics | K11: google-data-analytics | L11: Google | M11: 2025-10-16T00:41:18.854Z | O11: 0 | P11: 9 | Q11: No | R11: No | S11: akepb-central-male-qoy2h | T11: AKEPB - Central (Male) | U11: Google Career Certificates Scholarship Program | V11: xCh7v | Y11: No | Z11: 0 | AA11: On Zero % | AB11: +923488898281 | AC11: 7140108770097 | AD11: 37626 | AE11: Central (Rawalpindi / Lahore / Interior Punjab / Peshawar / etc) | AF11: Rawalpindi_Central Region | AG11: Central jamat khana rawalpindi | AH11: Male | AI11: Single | AJ11: Student | AK11: Below 25,000 | AL11: Entrepreneurship support and mentoring | AM11: 18-25 | AN11: FSc
A12: 1 | B12: 0 | C12: 1 | D12: 1 | E12: zeeshanwazir339@gmail.comGoogle Advanced Data Analytics | F12: 11 | G12: Zeeshan wazir | H12: zeeshanwazir339@gmail.com | I12: 7140303544757 | J12: Google Advanced Data Analytics | K12: google-advanced-data-analytics | L12: Google | M12: 2025-08-09T08:14:44.586Z | N12: 2025-11-02T08:21:54.307Z | O12: 5 | P12: 8 | Q12: No | R12: No | S12: akepb-gilgit-male-gxr0q | T12: AKEPB - Gilgit II (Male) | V12: xCh7v | Y12: No | Z12: 0.625 | AA12: <75% | AB12: +923555641737 | AC12: 7140303544757 | AD12: 37323 | AE12: Gilgit | AF12: Gilgit_Gilgit Region | AG12: sonikot | AH12: Male | AI12: Single | AJ12: Student | AK12: 60,000 - 80,000 | AL12: Job referrals or placement support | AM12: 18-25 | AN12: FSc
A13: 0 | B13: 0 | D13: 0 | E13: mahmud.shah@akhsp.orgGoogle IT Support | F13: 12 | G13: Mahmud Shah | H13: mahmud.shah@akhsp.org | I13: 3520217529755 | J13: Google IT Support | K13: google-it-support | L13: Google | M13: 2025-08-31T18:39:25.666Z | N13: 2025-09-28T01:59:16.808Z | O13: 0 | P13: 6 | Q13: No | R13: No | S13: akepb-central-male-qoy2h | T13: AKEPB - Central (Male) | V13: xCh7v | Y13: No | Z13: 0 | AA13: On Zero % | AB13: +923495423229 | AC13: 3520217529755 | AD13: 25569 | AE13: Central (Rawalpindi / Lahore / Interior Punjab / Peshawar / etc) | AF13: Rawalpindi_Central Region | AG13: Rawalpindi | AH13: Male | AI13: Married | AJ13: Employed | AK13: 100,001 - 120,000 | AL13: Enhance my skills in my current job | AM13: 46 and above | AN13: Masters
A14: 0 | B14: 0 | D14: 0 | E14: alisherctl.99@gmail.comGoogle Digital Marketing & E-commerce | F14: 13 | G14: Ali sher | H14: alisherctl.99@gmail.com | I14: 1520146085765 | J14: Google Digital Marketing & E-commerce | K14: google-digital-marketing-ecommerce | L14: Google | M14: 2025-10-05T18:47:12.628Z | O14: 0 | P14: 8 | Q14: No | R14: No | S14: akepb-central-male-qoy2h | T14: AKEPB - Central (Male) | U14: Google Career Certificates Scholarship Program | V14: xCh7v | Y14: No | Z14: 0 | AA14: On Zero % | AB14: +923449539220 | AC14: 1520146085765 | AD14: 37704 | AE14: Central (Rawalpindi / Lahore / Interior Punjab / Peshawar / etc) | AF14: Rawalpindi_Central Region | AG14: Golden jubilee jk rawalpindi | AH14: Male | AI14: Single | AJ14: Student | AK14: Below 25,000 | AL14: Participation in hackathons and innovation challenges | AM14: 18-25 | AN14: Bachelors
A15: 1 | B15: 0 | C15: 1 | D15: 1 | E15: inaararashmal@gmail.comGoogle Data Analytics | F15: 14 | G15: Inaara Murad | H15: inaararashmal@gmail.com | I15: 7140405746476 | J15: Google Data Analytics | K15: google-data-analytics | L15: Google | M15: 2025-07-23T12:29:27.236Z | N15: 2025-09-21T06:31:26.184Z | O15: 1 | P15: 9 | Q15: No | R15: No | S15: akepb-central-female-g5ddm | T15: AKEPB - Central (Female) | U15: Google Career Certificates Scholarship Program | Y15: No | Z15: 0.11111111 | AA15: <20% | AB15: +923554580112 | AC15: 7140405746476 | AD15: 37819 | AE15: Central (Rawalpindi / Lahore / Interior Punjab / Peshawar / etc) | AF15: Rawalpindi_Central Region | AG15: G9 karimabad jamatkhana | AH15: Female | AI15: Single | AJ15: Student | AK15: 25,000 - 50,000 | AL15: Internship placements | AM15: 18-25 | AN15: Bachelors
A16: 1 | B16: 0 | C16: 1 | D16: 1 | E16: alizubia62@gmail.comGoogle Data Analytics | F16: 15 | G16: Zubia Ali | H16: alizubia62@gmail.com | I16: 7140277375268 | J16: Google Data Analytics | K16: google-data-analytics | L16: Google | M16: 2025-08-02T22:55:03.202Z | N16: 2025-11-03T18:49:45.039Z | O16: 2 | P16: 9 | Q16: No | R16: No | S16: akepb-central-female-g5ddm | T16: AKEPB - Central (Female) | U16: Google Career Certificates Scholarship Program | Y16: No | Z16: 0.22222222 | AA16: <30% | AB16: +923169163008 | AC16: 7140277375268 | AD16: 38353 | AE16: Central (Rawalpindi / Lahore / Interior Punjab / Peshawar / etc) | AF16: Rawalpindi_Central Region | AG16: Pindi jamat khana | AH16: Female | AI16: Single | AJ16: Student | AK16: 60,000 - 80,000 | AL16: Advanced technical or soft skills training | AM16: 18-25 | AN16: Bachelors
A17: 1 | B17: 0 | C17: 1 | D17: 1 | E17: emanjehangir004@gmail.comGoogle Project Management | F17: 16 | G17: Eman Jehangir | H17: emanjehangir004@gmail.com | I17: 6110108021780 | J17: Google Project Management | K17: google-project-management | L17: Google | M17: 2025-07-26T14:17:18.803Z | O17: 0 | P17: 7 | Q17: No | R17: No | S17: akepb-central-female-g5ddm | T17: AKEPB - Central (Female) | V17: GgvHw | Y17: No | Z17: 0 | AA17: On Zero % | AB17: +923421502759 | AC17: 6110108021780 | AD17: 38230 | AE17: Central (Rawalpindi / Lahore / Interior Punjab / Peshawar / etc) | AF17: Rawalpindi_Central Region | AG17: Karimabad G-9 Jammatkhana | AH17: Female | AI17: Single | AJ17: Student | AK17: 80,001 - 100,000 | AL17: Advanced technical or soft skills training | AM17: 18-25 | AN17: FSc
A18: 0 | B18: 0 | D18: 0 | E18: nazeeraman93@gmail.comGoogle AI Essentials | F18: 17 | G18: Nazeer Aman | H18: nazeeraman93@gmail.com | I18: 7140253332139 | J18: Google AI Essentials | K18: ai-essentials-google | L18: Google | M18: 2025-07-23T10:07:01.489Z | N18: 2025-07-27T10:22:06.545Z | O18: 1 | P18: 5 | Q18: No | R18: No | S18: akepb-central-male-qoy2h | T18: AKEPB - Central (Male) | U18: Google Career Certificates Scholarship Program | V18: GgvHw | Y18: No | Z18: 0.2 | AA18: <20% | AB18: +923170580327 | AC18: 7140253332139 | AD18: 36589 | AE18: Central (Rawalpindi / Lahore / Interior Punjab / Peshawar / etc) | AF18: Rawalpindi_Central Region | AG18: Ismaili Jamatkhanaa Chandi Chowk Rawalpindi | AH18: Male | AI18: Single | AJ18: Unemployed | AK18: 25,000 - 50,000 | AL18: Advanced technical or soft skills training | AM18: 18-25 | AN18: Bachelors
A19: 0 | B19: 1 | D19: 0 | E19: hafsarehmat803@gmail.comGoogle Cybersecurity | F19: 18 | G19: Hafsa Rehmat | H19: hafsarehmat803@gmail.com | I19: 3840386030338 | J19: Google Cybersecurity | K19: google-cybersecurity | L19: Google | M19: 2025-07-23T18:44:42.350Z | N19: 2025-10-08T18:45:16.157Z | O19: 4 | P19: 9 | Q19: No | R19: No | S19: akepb-central-female-g5ddm | T19: AKEPB - Central (Female) | U19: Google Career Certificates Scholarship Program | V19: GgvHw | Y19: No | Z19: 0.44444444 | AA19: <50% | AB19: +923369416909 | AC19: 3840386030338 | AD19: 37865 | AE19: Central (Rawalpindi / Lahore / Interior Punjab / Peshawar / etc) | AF19: Rawalpindi_Central Region | AG19: Karimabad Jamat Khana Islamabad | AH19: Female | AI19: Single | AJ19: Student | AK19: 80,001 - 100,000 | AL19: Internship placements | AM19: 18-25 | AN19: FSc
A20: 0 | B20: 0 | D20: 0 | E20: alisherctl.99@gmail.comGoogle AI Essentials | F20: 19 | G20: Ali sher | H20: alisherctl.99@gmail.com | I20: 1520146085765 | J20: Google AI Essentials | K20: ai-essentials-google | L20: Google | M20: 2025-10-05T18:46:06.975Z | O20: 0 | P20: 5 | Q20: No | R20: No | S20: akepb-central-male-qoy2h | T20: AKEPB - Central (Male) | U20: Google Career Certificates Scholarship Program | V20: GgvHw | Y20: No | Z20: 0 | AA20: On Zero % | AB20: +923449539220 | AC20: 1520146085765 | AD20: 37704 | AE20: Central (Rawalpindi / Lahore / Interior Punjab / Peshawar / etc) | AF20: Rawalpindi_Central Region | AG20: Golden jubilee jk rawalpindi | AH20: Male | AI20: Single | AJ20: Student | AK20: Below 25,000 | AL20: Participation in hackathons and innovation challenges | AM20: 18-25 | AN20: Bachelors
A21: 0 | B21: 0 | D21: 0 | E21: uzmaaly0@gmail.comGoogle Data Analytics | F21: 20 | G21: Uzma paree | H21: uzmaaly0@gmail.com | I21: 7170305662552 | J21: Google Data Analytics | K21: google-data-analytics | L21: Google | M21: 2025-09-16T08:39:28.187Z | O21: 0 | P21: 9 | Q21: No | R21: No | S21: akepb-gilgit-female-1kkb4 | T21: AKEPB - Gilgit II (Female) | Y21: No | Z21: 0 | AA21: On Zero % | AB21: +923415766809 | AC21: 7170305662552 | AD21: 37244 | AE21: Gilgit | AF21: Gilgit_Gilgit Region | AG21: Zulifiqarabad jamatkhana | AH21: Female | AI21: Single | AJ21: Fresh Graduate | AK21: 60,000 - 80,000 | AL21: Support My Family members for Upskilling | AM21: 18-25 | AN21: Bachelors
A22: 1 | B22: 0 | C22: 1 | D22: 1 | E22: djhassanali986@gmail.comGoogle Data Analytics | F22: 21 | G22: Hassan ali | H22: djhassanali986@gmail.com | I22: 1520288940049 | J22: Google Data Analytics | K22: google-data-analytics | L22: Google | M22: 2025-07-24T03:12:45.799Z | N22: 2025-08-16T15:25:32.301Z | O22: 0 | P22: 9 | Q22: No | R22: No | S22: akepb-central-male-qoy2h | T22: AKEPB - Central (Male) | U22: Google Career Certificates Scholarship Program | V22: xCh7v | Y22: No | Z22: 0 | AA22: On Zero % | AB22: +923409860828 | AC22: 1520288940049 | AD22: 34390 | AE22: Central (Rawalpindi / Lahore / Interior Punjab / Peshawar / etc) | AF22: Rawalpindi_Central Region | AG22: Chandni chowk | AH22: Male | AI22: Single | AJ22: Employed | AK22: 60,000 - 80,000 | AL22: Job referrals or placement support | AM22: 26-35 | AN22: Masters
A23: 1 | B23: 0 | C23: 1 | D23: 1 | E23: shsaleemraza@gmail.comGoogle Project Management | F23: 22 | G23: Sheikh Saleem Raza | H23: shsaleemraza@gmail.com | I23: 3520227250785 | J23: Google Project Management | K23: google-project-management | L23: Google | M23: 2025-07-27T11:38:51.830Z | N23: 2025-07-27T11:47:00.632Z | O23: 0 | P23: 7 | Q23: No | R23: No | S23: akepb-central-male-qoy2h | T23: AKEPB - Central (Male) | U23: Google Career Certificates Scholarship Program | Y23: No | Z23: 0 | AA23: On Zero % | AB23: +923344010205 | AC23: 3520227250785 | AD23: 26394 | AE23: Central (Rawalpindi / Lahore / Interior Punjab / Peshawar / etc) | AF23: Lahore_Central Region | AG23: Lahore | AH23: Male | AI23: Married | AJ23: Employed | AK23: 180,000 - 200,000 | AL23: Advanced technical or soft skills training | AM23: 46 and above | AN23: Bachelors
A24: 0 | B24: 0 | D24: 0 | E24: sabiraansari54@gmail.comGoogle Data Analytics | F24: 23 | G24: Sabira Ansari | H24: sabiraansari54@gmail.com | I24: 1520290086362 | J24: Google Data Analytics | K24: google-data-analytics | L24: Google | M24: 2025-08-12T06:36:34.428Z | N24: 2025-10-29T10:18:16.496Z | O24: 6 | P24: 9 | Q24: No | R24: No | S24: akepb-central-female-g5ddm | T24: AKEPB - Central (Female) | V24: GgvHw | Y24: No | Z24: 0.66666667 | AA24: <75% | AB24: +923423325057 | AC24: 1520290086362 | AD24: 35471 | AE24: Central (Rawalpindi / Lahore / Interior Punjab / Peshawar / etc) | AF24: Rawalpindi_Central Region | AG24: Rawalpindi chandi Chowk | AH24: Female | AI24: Single | AJ24: Fresh Graduate | AK24: 60,000 - 80,000 | AL24: Entrepreneurship support and mentoring | AM24: 26-35 | AN24: Bachelors
A25: 1 | B25: 0 | C25: 1 | D25: 1 | E25: jibranali1112@gmail.comGoogle Digital Marketing & E-commerce | F25: 24 | G25: Jibran ali | H25: jibranali1112@gmail.com | I25: 7170203457325 | J25: Google Digital Marketing & E-commerce | K25: google-digital-marketing-ecommerce | L25: Google | M25: 2025-07-24T06:42:30.403Z | N25: 2025-11-02T10:27:42.294Z | O25: 2 | P25: 8 | Q25: No | R25: No | S25: akepb-gilgit-male-gxr0q | T25: AKEPB - Gilgit II (Male) | V25: xCh7v | Y25: No | Z25: 0.25 | AA25: <30% | AB25: +923144464908 | AC25: 7170203457325 | AD25: 37946 | AE25: Gilgit | AF25: Gilgit_Gilgit Region | AG25: Center jk | AH25: Male | AI25: Single | AJ25: Student | AK25: 80,001 - 100,000 | AL25: Entrepreneurship support and mentoring | AM25: 18-25 | AN25: FSc
A26: 0 | B26: 0 | D26: 0 | E26: Mubashiranwar95@gmail.comGoogle Cybersecurity | F26: 25 | G26: Mubashir Anwar | H26: Mubashiranwar95@gmail.com | I26: 1520252980589 | J26: Google Cybersecurity | K26: google-cybersecurity | L26: Google | M26: 2025-10-04T14:37:34.024Z | N26: 2025-10-04T15:17:20.808Z | O26: 0 | P26: 9 | Q26: No | R26: No | S26: akepb-central-male-qoy2h | T26: AKEPB - Central (Male) | U26: Google Career Certificates Scholarship Program | Y26: No | Z26: 0 | AA26: On Zero % | AB26: +923468069062 | AC26: 1520252980589 | AD26: 38062 | AE26: Central (Rawalpindi / Lahore / Interior Punjab / Peshawar / etc) | AF26: Peshawar_Central Region | AG26: Sikandar Town | AH26: Male | AI26: Single | AJ26: Student | AK26: 25,000 - 50,000 | AL26: Advanced technical or soft skills training | AM26: 18-25 | AN26: FSc
A27: 0 | B27: 0 | D27: 0 | E27: mashal.bsse@gmail.comGoogle IT Support | F27: 26 | G27: Mashal Ud din | H27: mashal.bsse@gmail.com | I27: 7150197972564 | J27: Google IT Support | K27: google-it-support | L27: Google | M27: 2025-07-25T06:51:36.917Z | N27: 2025-07-28T10:41:39.720Z | O27: 0 | P27: 6 | Q27: No | R27: No | S27: akepb-central-female-g5ddm | T27: AKEPB - Central (Female) | V27: GgvHw | Y27: No | Z27: 0 | AA27: On Zero % | AB27: +923466665110 | AC27: 7150197972564 | AD27: 36343 | AE27: Central (Rawalpindi / Lahore / Interior Punjab / Peshawar / etc) | AF27: Rawalpindi_Central Region | AG27: Rawalpindi JK | AH27: Female | AI27: Single | AJ27: Unemployed | AK27: 80,001 - 100,000 | AL27: Job referrals or placement support | AM27: 26-35 | AN27: Bachelors
A28: 0 | B28: 0 | D28: 0 | E28: waqas.ferwani198@gmail.comGoogle Data Analytics | F28: 27 | G28: waqas Ahmed | H28: waqas.ferwani198@gmail.com | I28: 7140261418847 | J28: Google Data Analytics | K28: google-data-analytics | L28: Google | M28: 2025-08-26T17:12:03.381Z | O28: 0 | P28: 9 | Q28: No | R28: No | S28: akepb-central-male-qoy2h | T28: AKEPB - Central (Male) | U28: Google Career Certificates Scholarship Program | V28: xCh7v | Y28: No | Z28: 0 | AA28: On Zero % | AB28: +923440562209 | AC28: 7140261418847 | AD28: 35828 | AE28: Central (Rawalpindi / Lahore / Interior Punjab / Peshawar / etc) | AF28: Rawalpindi_Central Region | AG28: Rawalpindi jk | AH28: Male | AI28: Single | AJ28: Employed | AK28: 100,001 - 120,000 | AL28: Entrepreneurship support and mentoring | AM28: 26-35 | AN28: FSc
A29: 0 | B29: 0 | D29: 0 | E29: azaamcna@gmail.comGoogle Project Management | F29: 28 | G29: Azaam | H29: azaamcna@gmail.com | I29: 1310166204003 | J29: Google Project Management | K29: google-project-management | L29: Google | M29: 2025-07-24T11:00:39.005Z | O29: 0 | P29: 6 | Q29: No | R29: No | S29: akepb-central-male-qoy2h | T29: AKEPB - Central (Male) | V29: xCh7v | Y29: No | Z29: 0 | AA29: On Zero % | AB29: +923279172151 | AC29: 1310166204003 | AD29: 37830 | AE29: Central (Rawalpindi / Lahore / Interior Punjab / Peshawar / etc) | AF29: Peshawar_Central Region | AG29: Abbottabad | AH29: Male | AI29: Single | AJ29: Student | AK29: 25,000 - 50,000 | AL29: Entrepreneurship support and mentoring | AM29: 18-25 | AN29: FSc
A30: 1 | B30: 0 | C30: 1 | D30: 1 | E30: inbox.sideeq@gmail.comGoogle Digital Marketing & E-commerce | F30: 29 | G30: Sideeq Akbar | H30: inbox.sideeq@gmail.com | I30: 1520257488921 | J30: Google Digital Marketing & E-commerce | K30: google-digital-marketing-ecommerce | L30: Google | M30: 2025-07-30T18:47:01.829Z | N30: 2025-07-30T19:31:38.124Z | O30: 0 | P30: 8 | Q30: No | R30: No | S30: akepb-central-male-qoy2h | T30: AKEPB - Central (Male) | U30: Google Career Certificates Scholarship Program | V30: xCh7v | Y30: No | Z30: 0 | AA30: On Zero % | AB30: +923409860749 | AC30: 1520257488921 | AD30: 35462 | AE30: Central (Rawalpindi / Lahore / Interior Punjab / Peshawar / etc) | AF30: Rawalpindi_Central Region | AG30: Rwp | AH30: Male | AI30: Single | AJ30: Employed | AK30: 60,000 - 80,000 | AL30: Entrepreneurship support and mentoring | AM30: 26-35 | AN30: Bachelors
A31: 0 | B31: 0 | D31: 0 | E31: zk311984@gmail.comGoogle Data Analytics | F31: 30 | G31: zahra khan | H31: zk311984@gmail.com | I31: 7170205711780 | J31: Google Data Analytics | K31: google-data-analytics | L31: Google | M31: 2025-07-26T04:20:55.932Z | N31: 2025-10-05T18:23:29.020Z | O31: 8 | P31: 9 | Q31: No | R31: No | S31: akepb-central-female-g5ddm | T31: AKEPB - Central (Female) | U31: Google Career Certificates Scholarship Program | Y31: No | Z31: 0.88888889 | AA31: <99% | AB31: +923181590695 | AC31: 7170205711780 | AD31: 37875 | AE31: Central (Rawalpindi / Lahore / Interior Punjab / Peshawar / etc) | AF31: Rawalpindi_Central Region | AG31: rawalpindi | AH31: Female | AI31: Single | AJ31: Unemployed | AK31: 80,001 - 100,000 | AL31: Job referrals or placement support | AM31: 18-25 | AN31: Bachelors
A32: 0 | B32: 0 | D32: 0 | E32: shahnazaliciqam@gmail.comGoogle Project Management | F32: 31 | G32: shehnaz | H32: shahnazaliciqam@gmail.com | I32: 7150264081608 | J32: Google Project Management | K32: google-project-management | L32: Google | M32: 2025-09-26T09:29:34.243Z | N32: 2025-09-27T12:22:05.182Z | O32: 1 | P32: 7 | Q32: No | R32: No | S32: akepb-central-female-g5ddm | T32: AKEPB - Central (Female) | U32: Google Career Certificates Scholarship Program | V32: GgvHw | Y32: No | Z32: 0.14285714 | AA32: <20% | AB32: +923180055149 | AC32: 7150264081608 | AD32: 35888 | AE32: Central (Rawalpindi / Lahore / Interior Punjab / Peshawar / etc) | AF32: Rawalpindi_Central Region | AG32: G9 | AH32: Female | AI32: Single | AJ32: Employed | AK32: 25,000 - 50,000 | AL32: Advanced technical or soft skills training | AM32: 26-35 | AN32: Bachelors
A33: 0 | B33: 0 | D33: 0 | E33: healthbytes024@gmail.comGoogle AI Essentials | F33: 32 | G33: Piyar Ali | H33: healthbytes024@gmail.com | I33: 7140303507631 | J33: Google AI Essentials | K33: ai-essentials-google | L33: Google | M33: 2025-10-27T17:42:42.273Z | N33: 2025-10-27T18:46:38.369Z | O33: 1 | P33: 5 | Q33: No | R33: No | S33: akepb-central-male-qoy2h | T33: AKEPB - Central (Male) | U33: Google Career Certificates Scholarship Program | V33: xCh7v | Y33: No | Z33: 0.2 | AA33: <20% | AB33: +923414136972 | AC33: 7140303507631 | AD33: 36753 | AE33: Central (Rawalpindi / Lahore / Interior Punjab / Peshawar / etc) | AF33: Lahore_Central Region | AG33: Lahore Davis Road | AH33: Male | AI33: Single | AJ33: Self Employed | AK33: 80,001 - 100,000 | AL33: Internship placements | AM33: 26-35 | AN33: FSc
A34: 0 | B34: 2 | D34: 0 | E34: girmmeen@gmail.comGoogle Data Analytics | F34: 33 | G34: Wajahat Sultan | H34: girmmeen@gmail.com | I34: 7140195844331 | J34: Google Data Analytics | K34: google-data-analytics | L34: Google | M34: 2025-10-24T11:58:55.453Z | N34: 2025-10-25T11:41:02.297Z | O34: 1 | P34: 9 | Q34: No | R34: No | S34: akepb-central-male-qoy2h | T34: AKEPB - Central (Male) | U34: Google Career Certificates Scholarship Program | V34: xCh7v | Y34: No | Z34: 0.11111111 | AA34: <20% | AB34: +923488146815 | AC34: 7140195844331 | AD34: 34069 | AE34: Central (Rawalpindi / Lahore / Interior Punjab / Peshawar / etc) | AF34: Rawalpindi_Central Region | AG34: Chandni Chowk Rwp | AH34: Male | AI34: Married | AJ34: Employed | AK34: 80,001 - 100,000 | AL34: Advanced technical or soft skills training | AM34: 26-35 | AN34: Masters
A35: 1 | B35: 0 | C35: 1 | D35: 1 | E35: alihmzazia@gmail.comGoogle Data Analytics | F35: 34 | G35: Ali Hamza Zia | H35: alihmzazia@gmail.com | I35: 3430186976493 | J35: Google Data Analytics | K35: google-data-analytics | L35: Google | M35: 2025-07-23T12:39:10.010Z | N35: 2025-08-16T03:13:39.378Z | O35: 0 | P35: 9 | Q35: No | R35: No | S35: akepb-central-male-qoy2h | T35: AKEPB - Central (Male) | U35: Google Career Certificates Scholarship Program | V35: xCh7v | Y35: No | Z35: 0 | AA35: On Zero % | AB35: +923217973696 | AC35: 3430186976493 | AD35: 35206 | AE35: Central (Rawalpindi / Lahore / Interior Punjab / Peshawar / etc) | AF35: Lahore_Central Region | AG35: Faisalabad | AH35: Male | AI35: Married | AJ35: Self Employed | AK35: 60,000 - 80,000 | AL35: Support My Family members for Upskilling | AM35: 26-35 | AN35: Bachelors
A36: 0 | B36: 1 | D36: 0 | E36: sammuhammad289@gmail.comGoogle Data Analytics | F36: 35 | G36: Muhammad Sami | H36: sammuhammad289@gmail.com | I36: 7150257656119 | J36: Google Data Analytics | K36: google-data-analytics | L36: Google | M36: 2025-08-21T06:33:48.117Z | N36: 2025-09-24T16:37:07.853Z | O36: 0 | P36: 9 | Q36: No | R36: No | S36: akepb-central-male-qoy2h | T36: AKEPB - Central (Male) | U36: Google Career Certificates Scholarship Program | Y36: No | Z36: 0 | AA36: On Zero % | AB36: +923411840755 | AC36: 7150257656119 | AD36: 38136 | AE36: Central (Rawalpindi / Lahore / Interior Punjab / Peshawar / etc) | AF36: Rawalpindi_Central Region | AG36: Ismaili Jamatkhanaa Chandi Chowk Rawalpindi | AH36: Male | AI36: Single | AJ36: Student | AK36: 80,001 - 100,000 | AL36: Advanced technical or soft skills training | AM36: 18-25 | AN36: FSc
A37: 0 | B37: 0 | D37: 0 | E37: sa2476professional@gmail.comGoogle Data Analytics | F37: 36 | G37: Shayan Ali | H37: sa2476professional@gmail.com | I37: 6110129910499 | J37: Google Data Analytics | K37: google-data-analytics | L37: Google | M37: 2025-08-05T14:13:48.629Z | N37: 2025-10-30T13:01:35.481Z | O37: 1 | P37: 9 | Q37: No | R37: No | S37: akepb-central-male-qoy2h | T37: AKEPB - Central (Male) | V37: xCh7v | Y37: No | Z37: 0.11111111 | AA37: <20% | AB37: +923093526530 | AC37: 6110129910499 | AD37: 37631 | AE37: Central (Rawalpindi / Lahore / Interior Punjab / Peshawar / etc) | AF37: Sargodha_Central Region | AG37: Main Sargodha JK | AH37: Male | AI37: Single | AJ37: Student | AK37: 25,000 - 50,000 | AL37: Advanced technical or soft skills training | AM37: 18-25 | AN37: FSc
A38: 1 | B38: 0 | C38: 1 | D38: 1 | E38: salmanullah.baig@gmail.comGoogle IT Automation with Python | F38: 37 | G38: salman ullah baig | H38: salmanullah.baig@gmail.com | I38: 7140253806125 | J38: Google IT Automation with Python | K38: google-it-automation | L38: Google | M38: 2025-07-27T08:24:20.510Z | N38: 2025-08-25T13:50:40.306Z | O38: 0 | P38: 7 | Q38: No | R38: No | S38: akepb-central-male-qoy2h | T38: AKEPB - Central (Male) | U38: Google Career Certificates Scholarship Program | Y38: No | Z38: 0 | AA38: On Zero % | AB38: +923155597447 | AC38: 7140253806125 | AD38: 35248 | AE38: Central (Rawalpindi / Lahore / Interior Punjab / Peshawar / etc) | AF38: Rawalpindi_Central Region | AG38: G9/1 JK | AH38: Male | AI38: Single | AJ38: Self Employed | AK38: 180,000 - 200,000 | AL38: Advanced technical or soft skills training | AM38: 26-35 | AN38: Bachelors
A39: 0 | B39: 0 | D39: 0 | E39: healthbytes024@gmail.comGoogle Digital Marketing & E-commerce | F39: 38 | G39: Piyar Ali | H39: healthbytes024@gmail.com | I39: 7140303507631 | J39: Google Digital Marketing & E-commerce | K39: google-digital-marketing-ecommerce | L39: Google | M39: 2025-07-23T10:21:03.504Z | N39: 2025-09-02T19:27:40.760Z | O39: 1 | P39: 8 | Q39: No | R39: No | S39: akepb-central-male-qoy2h | T39: AKEPB - Central (Male) | U39: Google Career Certificates Scholarship Program | Y39: No | Z39: 0.125 | AA39: <20% | AB39: +923414136972 | AC39: 7140303507631 | AD39: 36753 | AE39: Central (Rawalpindi / Lahore / Interior Punjab / Peshawar / etc) | AF39: Lahore_Central Region | AG39: Lahore Davis Road | AH39: Male | AI39: Single | AJ39: Self Employed | AK39: 80,001 - 100,000 | AL39: Internship placements | AM39: 26-35 | AN39: FSc
A40: 1 | B40: 0 | C40: 1 | D40: 1 | E40: waqaralam654@gmail.comGoogle Project Management | F40: 39 | G40: Waqar Alam | H40: waqaralam654@gmail.com | I40: 7150171735503 | J40: Google Project Management | K40: google-project-management | L40: Google | M40: 2025-08-13T18:50:26.142Z | N40: 2025-08-13T20:37:57.450Z | O40: 0 | P40: 7 | Q40: No | R40: No | S40: akepb-central-male-qoy2h | T40: AKEPB - Central (Male) | U40: Google Career Certificates Scholarship Program | Y40: No | Z40: 0 | AA40: On Zero % | AB40: +923459032564 | AC40: 7150171735503 | AD40: 35961 | AE40: Central (Rawalpindi / Lahore / Interior Punjab / Peshawar / etc) | AF40: Rawalpindi_Central Region | AG40: Karimabad | AH40: Male | AI40: Single | AJ40: Student | AK40: 80,001 - 100,000 | AL40: Entrepreneurship support and mentoring | AM40: 26-35 | AN40: Masters
...

Sheet National Dashboard
A1: GCC-Dashboard -(Pak Level) as of 5th Nov-2025
D5: Candidates Invited | H5: Candidates started any one course | L5: No. of Courses Registered | U5: Total Candidates not started any course
D7: =GETPIVOTDATA("Total Enrollment",'National Pivot'!$A$3) -> 1732 | H7: =+D7-U7 -> 1326 | L7: =GETPIVOTDATA("Sum of One verses Program Registered",'National Pivot'!$A$3) -> 2038 | U7: =GETPIVOTDATA("Unique Id",'National Pivot'!$H$4) -> 406
D8: M | E8: =GETPIVOTDATA("Sum of Count for Enrollment",'National Pivot'!$A$120,"Gender","Male") -> 918 | F8: =+E8/D7 -> 0.53002309 | H8: M | I8: =GETPIVOTDATA("Course Started",'National Pivot'!$A$120,"Gender","Male") -> 745 | J8: =I8/H7 -> 0.56184012 | U8: M | V8: =GETPIVOTDATA("Course Not started",'National Pivot'!$A$120,"Gender","Male") -> 173 | W8: =+V8/U7 -> 0.42610837
D9: F | E9: =GETPIVOTDATA("Sum of Count for Enrollment",'National Pivot'!$A$120,"Gender","Female") -> 700 | F9: =E9/D7 -> 0.40415704 | H9: F | I9: =GETPIVOTDATA("Course Started",'National Pivot'!$A$120,"Gender","Female") -> 548 | J9: =I9/H7 -> 0.413273 | U9: F | V9: =GETPIVOTDATA("Course Not started",'National Pivot'!$A$120,"Gender","Female") -> 152 | W9: =+V9/U7 -> 0.37438424
M27: No. of Candidates Completed 1 course | P27: Total no. of Course Completed
M29: =GETPIVOTDATA("Total Enrollment",'National Pivot'!$A$33) -> 247 | P29: =GETPIVOTDATA("Count of Count for Yes",'National Pivot'!$A$33) -> 341
C50: No. of Candidates | F50: Total no. of Course >50% Completion | L50: No. of Candidates | O50: Total no. of Course < 50% Completion | V50: No. of Candidates | Y50: Total no. of Course on 0% Completion
C52: =GETPIVOTDATA("Total Enrollment",'National Pivot'!$O$33) -> 78 | F52: =GETPIVOTDATA("Count of Specialization",'National Pivot'!$O$33) -> 119 | L52: =GETPIVOTDATA("Total Enrollment",'National Pivot'!$G$33) -> 396 | O52: =GETPIVOTDATA("Count of Specialization",'National Pivot'!$G$33) -> 622 | V52: =GETPIVOTDATA("Total Enrollment",'National Pivot'!$K$33) -> 605 | Y52: =GETPIVOTDATA("Count of Specialization",'National Pivot'!$K$33) -> 956

Sheet Region Wise Dashboard
A1: =CONCATENATE("GCC Dashboard for"," ",'Regions Pivot'!P1," as of 5th Nov 2025") -> GCC Dashboard for Southern (Karachi / Interior Sindh) as of 5th Nov 2025
F10: Candidates Invited | J10: Candidates started any one course | O10: No. of Courses Registered
F12: =GETPIVOTDATA("Sum of Count for Enrollment",'Regions Pivot'!$A$3) -> 585 | J12: =GETPIVOTDATA("Sum of Count for Candiodates started course",'Regions Pivot'!$A$3) -> 501 | O12: =GETPIVOTDATA("Count of Specialization",'Regions Pivot'!$A$3) -> 840
K31: Candidates not started Program
K33: =GETPIVOTDATA("Unique Id",'Regions Pivot'!$I$4) -> 84
I55: Candidates on 100% Completion | N55: No. of Courses Completed
I57: =GETPIVOTDATA("Candidates",'Regions Pivot'!$A$29) -> 134 | N57: =GETPIVOTDATA("Courses Completed",'Regions Pivot'!$A$29) -> 211
I75: Candidates on >50% Completion | N75: No. of Courses >50%
I77: =GETPIVOTDATA("Candidates",'Regions Pivot'!$E$29) -> 39 | N77: =GETPIVOTDATA("Courses Completed",'Regions Pivot'!$E$29) -> 61
I97: Candidates on <50% Completion | N97: No. of Courses <50%
I99: =GETPIVOTDATA("Candidates",'Regions Pivot'!$J$29) -> 129 | N99: =GETPIVOTDATA("Courses Completed",'Regions Pivot'!$J$29) -> 233
I119: Candidates on 0% Completion | N119: No. of Courses 0%
I121: =GETPIVOTDATA("Candidates",'Regions Pivot'!$P$29) -> 201 | N121: =GETPIVOTDATA("Courses Completed",'Regions Pivot'!$P$29) -> 337
